Traceback (most recent call last):2020-03-21 01:09:16
  File "/usr/lib/python3.6/socket.py", line 713, in create_connection    sock.connect(sa)
ConnectionRefusedError: [Errno 111] Connection refused2020-03-21 01:09:16
------------------------log_info--------------------------------
Traceback (most recent call last):2020-03-21 01:09:19
  File "/usr/lib/python3.6/socket.py", line 713, in create_connection    sock.connect(sa)
ConnectionRefusedError: [Errno 111] Connection refused2020-03-21 01:09:19
------------------------log_info--------------------------------
Traceback (most recent call last):2020-03-21 01:09:19
  File "/usr/lib/python3.6/socket.py", line 713, in create_connection    sock.connect(sa)
ConnectionRefusedError: [Errno 111] Connection refused2020-03-21 01:09:19
------------------------log_info--------------------------------
Traceback (most recent call last):2020-03-21 15:00:30
  File "/home/user_szz/.local/lib/python3.6/site-packages/yaml/parser.py", line 174, in parse_document_start    self.peek_token().start_mark)
yaml.parser.ParserError: expected '<document start>', but found '{'2020-03-21 15:00:30  in "user_account.yaml", line 2, column 12020-03-21 15:00:30
------------------------log_info--------------------------------
Traceback (most recent call last):2020-03-21 15:11:33
  File "/home/user_szz/.local/lib/python3.6/site-packages/yaml/parser.py", line 439, in parse_block_mapping_key    "expected <block end>, but found %r" % token.id, token.start_mark)
yaml.parser.ParserError: while parsing a block mapping2020-03-21 15:11:33  in "user_account.yml", line 1, column 12020-03-21 15:11:33expected <block end>, but found '-'2020-03-21 15:11:33  in "user_account.yml", line 7, column 12020-03-21 15:11:33
------------------------log_info--------------------------------
